Workbook

Sheet Gruppi_Atleti
A1: ID Gruppo | B1: Nome Gruppo | C1: Allenatore | D1: Atleta | E1: Contatto atleta | F1: Certificato medico (S/N) | G1: Scadenza certificato | H1: Presenze | I1: Assenze | J1: Recuperi fatti | K1: Recuperi da programmare | L1: Quota totale stagione | M1: Quota associativa (una tantum) | N1: Quota pagata | O1: Saldo da pagare | P1: Semaforo certificato | Q1: Semaforo pagamenti | R1: altri pagamenti non bonif.
A2: 1 | B2: Gruppo 1 | C2: Matteo Bosso | D2: Alberto Mantovani | F2: agonistico | G2: 46379 | H2: =COUNTIFS(Presenze!$D:$D,D2,Presenze!$E:$E,"S") -> 0 | I2: =COUNTIFS(Presenze!$D:$D,D2,Presenze!$F:$F,"S") -> 0 | J2: =COUNTIFS(Presenze!$D:$D,D2,Presenze!$G:$G,"<>") -> 0 | K2: =I2-J2 -> 0 | L2: 480 | M2: 15 | N2: 255 | O2: =L2+M2-N2 -> 240 | P2: =IF(OR(F2="nessuno",F2=""),"🔴",IF(AND(OR(F2="agonistico",F2="non agonistico"),G2<TODAY()),"🔴",IF(AND(OR(F2="agonistico",F2="non agonistico"),G2<=TODAY()+30),"🟡","🟢"))) -> 🟢 | Q2: =IF((L2+M2)<=0,"🟢",IF(N2<=0,"🔴",IF(O2>0,"🟡","🟢"))) -> 🟡
A3: 1 | B3: Gruppo 1 | C3: Matteo Bosso | D3: Damiano Maccacaro | F3: non agonistico | G3: 46346 | H3: =COUNTIFS(Presenze!$D:$D,D3,Presenze!$E:$E,"S") -> 0 | I3: =COUNTIFS(Presenze!$D:$D,D3,Presenze!$F:$F,"S") -> 0 | J3: =COUNTIFS(Presenze!$D:$D,D3,Presenze!$G:$G,"<>") -> 0 | K3: =I3-J3 -> 0 | L3: 670 | M3: 15 | N3: 255 | O3: =L3+M3-N3 -> 430 | P3: =IF(OR(F3="nessuno",F3=""),"🔴",IF(AND(OR(F3="agonistico",F3="non agonistico"),G3<TODAY()),"🔴",IF(AND(OR(F3="agonistico",F3="non agonistico"),G3<=TODAY()+30),"🟡","🟢"))) -> 🟢 | Q3: =IF((L3+M3)<=0,"🟢",IF(N3<=0,"🔴",IF(O3>0,"🟡","🟢"))) -> 🟡
A4: 1 | B4: Gruppo 1 | C4: Matteo Bosso | D4: Nicola Baiocco | F4: non agonistico | G4: 46328 | H4: =COUNTIFS(Presenze!$D:$D,D4,Presenze!$E:$E,"S") -> 0 | I4: =COUNTIFS(Presenze!$D:$D,D4,Presenze!$F:$F,"S") -> 0 | J4: =COUNTIFS(Presenze!$D:$D,D4,Presenze!$G:$G,"<>") -> 0 | K4: =I4-J4 -> 0 | L4: 480 | M4: 15 | N4: 255 | O4: =L4+M4-N4 -> 240 | P4: =IF(OR(F4="nessuno",F4=""),"🔴",IF(AND(OR(F4="agonistico",F4="non agonistico"),G4<TODAY()),"🔴",IF(AND(OR(F4="agonistico",F4="non agonistico"),G4<=TODAY()+30),"🟡","🟢"))) -> 🟢 | Q4: =IF((L4+M4)<=0,"🟢",IF(N4<=0,"🔴",IF(O4>0,"🟡","🟢"))) -> 🟡
A5: 1 | B5: Gruppo 1 | C5: Matteo Bosso | D5: Marco Pinelli | F5: agonistico | G5: 46308 | H5: =COUNTIFS(Presenze!$D:$D,D5,Presenze!$E:$E,"S") -> 0 | I5: =COUNTIFS(Presenze!$D:$D,D5,Presenze!$F:$F,"S") -> 0 | J5: =COUNTIFS(Presenze!$D:$D,D5,Presenze!$G:$G,"<>") -> 0 | K5: =I5-J5 -> 0 | L5: 860 | M5: 15 | N5: 445 | O5: =L5+M5-N5 -> 430 | P5: =IF(OR(F5="nessuno",F5=""),"🔴",IF(AND(OR(F5="agonistico",F5="non agonistico"),G5<TODAY()),"🔴",IF(AND(OR(F5="agonistico",F5="non agonistico"),G5<=TODAY()+30),"🟡","🟢"))) -> 🟢 | Q5: =IF((L5+M5)<=0,"🟢",IF(N5<=0,"🔴",IF(O5>0,"🟡","🟢"))) -> 🟡
A6: 1 | B6: Gruppo 1 | C6: Matteo Bosso | D6: Massimiliano Dorella | F6: agonistico | G6: 46331 | H6: =COUNTIFS(Presenze!$D:$D,D6,Presenze!$E:$E,"S") -> 0 | I6: =COUNTIFS(Presenze!$D:$D,D6,Presenze!$F:$F,"S") -> 0 | J6: =COUNTIFS(Presenze!$D:$D,D6,Presenze!$G:$G,"<>") -> 0 | K6: =I6-J6 -> 0 | L6: 670 | M6: 15 | N6: 445 | O6: =L6+M6-N6 -> 240 | P6: =IF(OR(F6="nessuno",F6=""),"🔴",IF(AND(OR(F6="agonistico",F6="non agonistico"),G6<TODAY()),"🔴",IF(AND(OR(F6="agonistico",F6="non agonistico"),G6<=TODAY()+30),"🟡","🟢"))) -> 🟢 | Q6: =IF((L6+M6)<=0,"🟢",IF(N6<=0,"🔴",IF(O6>0,"🟡","🟢"))) -> 🟡 | R6: PAYPAL
A7: 1 | B7: Gruppo 1 | C7: Matteo Bosso | D7: Emilio Telluri | F7: agonistico | G7: 46288 | H7: =COUNTIFS(Presenze!$D:$D,D7,Presenze!$E:$E,"S") -> 0 | I7: =COUNTIFS(Presenze!$D:$D,D7,Presenze!$F:$F,"S") -> 0 | J7: =COUNTIFS(Presenze!$D:$D,D7,Presenze!$G:$G,"<>") -> 0 | K7: =I7-J7 -> 0 | L7: 480 | M7: 15 | N7: 255 | O7: =L7+M7-N7 -> 240 | P7: =IF(OR(F7="nessuno",F7=""),"🔴",IF(AND(OR(F7="agonistico",F7="non agonistico"),G7<TODAY()),"🔴",IF(AND(OR(F7="agonistico",F7="non agonistico"),G7<=TODAY()+30),"🟡","🟢"))) -> 🟢 | Q7: =IF((L7+M7)<=0,"🟢",IF(N7<=0,"🔴",IF(O7>0,"🟡","🟢"))) -> 🟡
A8: 1 | B8: Gruppo 1 | C8: Matteo Bosso | D8: Pulvini Matteo | F8: agonistico | G8: 46346 | H8: =COUNTIFS(Presenze!$D:$D,D8,Presenze!$E:$E,"S") -> 0 | I8: =COUNTIFS(Presenze!$D:$D,D8,Presenze!$F:$F,"S") -> 0 | J8: =COUNTIFS(Presenze!$D:$D,D8,Presenze!$G:$G,"<>") -> 0 | K8: =I8-J8 -> 0 | L8: 480 | M8: 15 | N8: 255 | O8: =L8+M8-N8 -> 240 | P8: =IF(OR(F8="nessuno",F8=""),"🔴",IF(AND(OR(F8="agonistico",F8="non agonistico"),G8<TODAY()),"🔴",IF(AND(OR(F8="agonistico",F8="non agonistico"),G8<=TODAY()+30),"🟡","🟢"))) -> 🟢 | Q8: =IF((L8+M8)<=0,"🟢",IF(N8<=0,"🔴",IF(O8>0,"🟡","🟢"))) -> 🟡
A9: 1 | B9: Gruppo 1 | C9: Matteo Bosso | D9: Cristian Costa | F9: agonistico | G9: 46261 | H9: =COUNTIFS(Presenze!$D:$D,D9,Presenze!$E:$E,"S") -> 0 | I9: =COUNTIFS(Presenze!$D:$D,D9,Presenze!$F:$F,"S") -> 0 | J9: =COUNTIFS(Presenze!$D:$D,D9,Presenze!$G:$G,"<>") -> 0 | K9: =I9-J9 -> 0 | L9: 480 | M9: 15 | N9: 255 | O9: =L9+M9-N9 -> 240 | P9: =IF(OR(F9="nessuno",F9=""),"🔴",IF(AND(OR(F9="agonistico",F9="non agonistico"),G9<TODAY()),"🔴",IF(AND(OR(F9="agonistico",F9="non agonistico"),G9<=TODAY()+30),"🟡","🟢"))) -> 🟢 | Q9: =IF((L9+M9)<=0,"🟢",IF(N9<=0,"🔴",IF(O9>0,"🟡","🟢"))) -> 🟡
A10: 2 | B10: Gruppo 2 | C10: Elena Colombi | D10: Cecilia Bertolo | F10: agonistico | G10: 46357 | H10: =COUNTIFS(Presenze!$D:$D,D10,Presenze!$E:$E,"S") -> 0 | I10: =COUNTIFS(Presenze!$D:$D,D10,Presenze!$F:$F,"S") -> 0 | J10: =COUNTIFS(Presenze!$D:$D,D10,Presenze!$G:$G,"<>") -> 0 | K10: =I10-J10 -> 0 | L10: 480 | M10: 15 | N10: 255 | O10: =L10+M10-N10 -> 240 | P10: =IF(OR(F10="nessuno",F10=""),"🔴",IF(AND(OR(F10="agonistico",F10="non agonistico"),G10<TODAY()),"🔴",IF(AND(OR(F10="agonistico",F10="non agonistico"),G10<=TODAY()+30),"🟡","🟢"))) -> 🟢 | Q10: =IF((L10+M10)<=0,"🟢",IF(N10<=0,"🔴",IF(O10>0,"🟡","🟢"))) -> 🟡
A11: 2 | B11: Gruppo 2 | C11: Elena Colombi | D11: Serena Bellinazzi | F11: agonistico | G11: 46160 | H11: =COUNTIFS(Presenze!$D:$D,D11,Presenze!$E:$E,"S") -> 0 | I11: =COUNTIFS(Presenze!$D:$D,D11,Presenze!$F:$F,"S") -> 0 | J11: =COUNTIFS(Presenze!$D:$D,D11,Presenze!$G:$G,"<>") -> 0 | K11: =I11-J11 -> 0 | L11: 480 | M11: 15 | N11: 255 | O11: =L11+M11-N11 -> 240 | P11: =IF(OR(F11="nessuno",F11=""),"🔴",IF(AND(OR(F11="agonistico",F11="non agonistico"),G11<TODAY()),"🔴",IF(AND(OR(F11="agonistico",F11="non agonistico"),G11<=TODAY()+30),"🟡","🟢"))) -> 🟢 | Q11: =IF((L11+M11)<=0,"🟢",IF(N11<=0,"🔴",IF(O11>0,"🟡","🟢"))) -> 🟡
A12: 2 | B12: Gruppo 2 | C12: Elena Colombi | D12: Desiree Mastrosimone | F12: agonistico | G12: 46009 | H12: =COUNTIFS(Presenze!$D:$D,D12,Presenze!$E:$E,"S") -> 0 | I12: =COUNTIFS(Presenze!$D:$D,D12,Presenze!$F:$F,"S") -> 0 | J12: =COUNTIFS(Presenze!$D:$D,D12,Presenze!$G:$G,"<>") -> 0 | K12: =I12-J12 -> 0 | L12: 480 | M12: 15 | N12: 255 | O12: =L12+M12-N12 -> 240 | P12: =IF(OR(F12="nessuno",F12=""),"🔴",IF(AND(OR(F12="agonistico",F12="non agonistico"),G12<TODAY()),"🔴",IF(AND(OR(F12="agonistico",F12="non agonistico"),G12<=TODAY()+30),"🟡","🟢"))) -> 🔴 | Q12: =IF((L12+M12)<=0,"🟢",IF(N12<=0,"🔴",IF(O12>0,"🟡","🟢"))) -> 🟡
A13: 2 | B13: Gruppo 2 | C13: Elena Colombi | D13: Anita Conti | F13: agonistico | G13: 46365 | H13: =COUNTIFS(Presenze!$D:$D,D13,Presenze!$E:$E,"S") -> 0 | I13: =COUNTIFS(Presenze!$D:$D,D13,Presenze!$F:$F,"S") -> 0 | J13: =COUNTIFS(Presenze!$D:$D,D13,Presenze!$G:$G,"<>") -> 0 | K13: =I13-J13 -> 0 | L13: 480 | M13: 15 | N13: 255 | O13: =L13+M13-N13 -> 240 | P13: =IF(OR(F13="nessuno",F13=""),"🔴",IF(AND(OR(F13="agonistico",F13="non agonistico"),G13<TODAY()),"🔴",IF(AND(OR(F13="agonistico",F13="non agonistico"),G13<=TODAY()+30),"🟡","🟢"))) -> 🟢 | Q13: =IF((L13+M13)<=0,"🟢",IF(N13<=0,"🔴",IF(O13>0,"🟡","🟢"))) -> 🟡
A14: 2 | B14: Gruppo 2 | C14: Elena Colombi | D14: Massimiliana Della Camera | F14: agonistico | G14: 46325 | H14: =COUNTIFS(Presenze!$D:$D,D14,Presenze!$E:$E,"S") -> 0 | I14: =COUNTIFS(Presenze!$D:$D,D14,Presenze!$F:$F,"S") -> 0 | J14: =COUNTIFS(Presenze!$D:$D,D14,Presenze!$G:$G,"<>") -> 0 | K14: =I14-J14 -> 0 | L14: 480 | M14: 15 | N14: 255 | O14: =L14+M14-N14 -> 240 | P14: =IF(OR(F14="nessuno",F14=""),"🔴",IF(AND(OR(F14="agonistico",F14="non agonistico"),G14<TODAY()),"🔴",IF(AND(OR(F14="agonistico",F14="non agonistico"),G14<=TODAY()+30),"🟡","🟢"))) -> 🟢 | Q14: =IF((L14+M14)<=0,"🟢",IF(N14<=0,"🔴",IF(O14>0,"🟡","🟢"))) -> 🟡
A15: 2 | B15: Gruppo 2 | C15: Elena Colombi | D15: Valentina Pisani | F15: non agonistico | G15: 46283 | H15: =COUNTIFS(Presenze!$D:$D,D15,Presenze!$E:$E,"S") -> 0 | I15: =COUNTIFS(Presenze!$D:$D,D15,Presenze!$F:$F,"S") -> 0 | J15: =COUNTIFS(Presenze!$D:$D,D15,Presenze!$G:$G,"<>") -> 0 | K15: =I15-J15 -> 0 | L15: 480 | M15: 15 | N15: 255 | O15: =L15+M15-N15 -> 240 | P15: =IF(OR(F15="nessuno",F15=""),"🔴",IF(AND(OR(F15="agonistico",F15="non agonistico"),G15<TODAY()),"🔴",IF(AND(OR(F15="agonistico",F15="non agonistico"),G15<=TODAY()+30),"🟡","🟢"))) -> 🟢 | Q15: =IF((L15+M15)<=0,"🟢",IF(N15<=0,"🔴",IF(O15>0,"🟡","🟢"))) -> 🟡
A16: 2 | B16: Gruppo 2 | C16: Elena Colombi | D16: Anna Cona | F16: agonistico | G16: 46286 | H16: =COUNTIFS(Presenze!$D:$D,D16,Presenze!$E:$E,"S") -> 0 | I16: =COUNTIFS(Presenze!$D:$D,D16,Presenze!$F:$F,"S") -> 0 | J16: =COUNTIFS(Presenze!$D:$D,D16,Presenze!$G:$G,"<>") -> 0 | K16: =I16-J16 -> 0 | L16: 730 | M16: 15 | N16: =255+490 -> 745 | O16: =L16+M16-N16 -> 0 | P16: =IF(OR(F16="nessuno",F16=""),"🔴",IF(AND(OR(F16="agonistico",F16="non agonistico"),G16<TODAY()),"🔴",IF(AND(OR(F16="agonistico",F16="non agonistico"),G16<=TODAY()+30),"🟡","🟢"))) -> 🟢 | Q16: =IF((L16+M16)<=0,"🟢",IF(N16<=0,"🔴",IF(O16>0,"🟡","🟢"))) -> 🟢 | R16: CASH OMAR
A17: 2 | B17: Gruppo 2 | C17: Elena Colombi | D17: Federica Cona | F17: agonistico | G17: 46346 | H17: =COUNTIFS(Presenze!$D:$D,D17,Presenze!$E:$E,"S") -> 0 | I17: =COUNTIFS(Presenze!$D:$D,D17,Presenze!$F:$F,"S") -> 0 | J17: =COUNTIFS(Presenze!$D:$D,D17,Presenze!$G:$G,"<>") -> 0 | K17: =I17-J17 -> 0 | L17: 860 | M17: 15 | N17: 445 | O17: =L17+M17-N17 -> 430 | P17: =IF(OR(F17="nessuno",F17=""),"🔴",IF(AND(OR(F17="agonistico",F17="non agonistico"),G17<TODAY()),"🔴",IF(AND(OR(F17="agonistico",F17="non agonistico"),G17<=TODAY()+30),"🟡","🟢"))) -> 🟢 | Q17: =IF((L17+M17)<=0,"🟢",IF(N17<=0,"🔴",IF(O17>0,"🟡","🟢"))) -> 🟡
A18: 3 | B18: Gruppo 3 | C18: Matteo Bosso | D18: Matteo Bertani | F18: agonistico | G18: 46394 | H18: =COUNTIFS(Presenze!$D:$D,D18,Presenze!$E:$E,"S") -> 0 | I18: =COUNTIFS(Presenze!$D:$D,D18,Presenze!$F:$F,"S") -> 0 | J18: =COUNTIFS(Presenze!$D:$D,D18,Presenze!$G:$G,"<>") -> 0 | K18: =I18-J18 -> 0 | L18: 480 | M18: 15 | N18: 255 | O18: =L18+M18-N18 -> 240 | P18: =IF(OR(F18="nessuno",F18=""),"🔴",IF(AND(OR(F18="agonistico",F18="non agonistico"),G18<TODAY()),"🔴",IF(AND(OR(F18="agonistico",F18="non agonistico"),G18<=TODAY()+30),"🟡","🟢"))) -> 🟢 | Q18: =IF((L18+M18)<=0,"🟢",IF(N18<=0,"🔴",IF(O18>0,"🟡","🟢"))) -> 🟡
A19: 3 | B19: Gruppo 3 | C19: Matteo Bosso | D19: Agostino Cianciulli | F19: non agonistico | G19: 46292 | H19: =COUNTIFS(Presenze!$D:$D,D19,Presenze!$E:$E,"S") -> 0 | I19: =COUNTIFS(Presenze!$D:$D,D19,Presenze!$F:$F,"S") -> 0 | J19: =COUNTIFS(Presenze!$D:$D,D19,Presenze!$G:$G,"<>") -> 0 | K19: =I19-J19 -> 0 | L19: 860 | M19: 15 | N19: 445 | O19: =L19+M19-N19 -> 430 | P19: =IF(OR(F19="nessuno",F19=""),"🔴",IF(AND(OR(F19="agonistico",F19="non agonistico"),G19<TODAY()),"🔴",IF(AND(OR(F19="agonistico",F19="non agonistico"),G19<=TODAY()+30),"🟡","🟢"))) -> 🟢 | Q19: =IF((L19+M19)<=0,"🟢",IF(N19<=0,"🔴",IF(O19>0,"🟡","🟢"))) -> 🟡
A20: 3 | B20: Gruppo 3 | C20: Matteo Bosso | D20: Andrea Simonetti | H20: =COUNTIFS(Presenze!$D:$D,D20,Presenze!$E:$E,"S") -> 0 | I20: =COUNTIFS(Presenze!$D:$D,D20,Presenze!$F:$F,"S") -> 0 | J20: =COUNTIFS(Presenze!$D:$D,D20,Presenze!$G:$G,"<>") -> 0 | K20: =I20-J20 -> 0 | L20: 480 | M20: 15 | N20: 255 | O20: =L20+M20-N20 -> 240 | P20: =IF(OR(F20="nessuno",F20=""),"🔴",IF(AND(OR(F20="agonistico",F20="non agonistico"),G20<TODAY()),"🔴",IF(AND(OR(F20="agonistico",F20="non agonistico"),G20<=TODAY()+30),"🟡","🟢"))) -> 🔴 | Q20: =IF((L20+M20)<=0,"🟢",IF(N20<=0,"🔴",IF(O20>0,"🟡","🟢"))) -> 🟡
A21: 3 | B21: Gruppo 3 | C21: Matteo Bosso | D21: Roberto d’Intino | F21: non agonistico | G21: 46318 | H21: =COUNTIFS(Presenze!$D:$D,D21,Presenze!$E:$E,"S") -> 0 | I21: =COUNTIFS(Presenze!$D:$D,D21,Presenze!$F:$F,"S") -> 0 | J21: =COUNTIFS(Presenze!$D:$D,D21,Presenze!$G:$G,"<>") -> 0 | K21: =I21-J21 -> 0 | L21: 480 | M21: 15 | N21: 255 | O21: =L21+M21-N21 -> 240 | P21: =IF(OR(F21="nessuno",F21=""),"🔴",IF(AND(OR(F21="agonistico",F21="non agonistico"),G21<TODAY()),"🔴",IF(AND(OR(F21="agonistico",F21="non agonistico"),G21<=TODAY()+30),"🟡","🟢"))) -> 🟢 | Q21: =IF((L21+M21)<=0,"🟢",IF(N21<=0,"🔴",IF(O21>0,"🟡","🟢"))) -> 🟡
A22: 3 | B22: Gruppo 3 | C22: Matteo Bosso | D22: Federico Marcolini | F22: non agonistico | G22: 46158 | H22: =COUNTIFS(Presenze!$D:$D,D22,Presenze!$E:$E,"S") -> 0 | I22: =COUNTIFS(Presenze!$D:$D,D22,Presenze!$F:$F,"S") -> 0 | J22: =COUNTIFS(Presenze!$D:$D,D22,Presenze!$G:$G,"<>") -> 0 | K22: =I22-J22 -> 0 | L22: 480 | M22: 15 | N22: 255 | O22: =L22+M22-N22 -> 240 | P22: =IF(OR(F22="nessuno",F22=""),"🔴",IF(AND(OR(F22="agonistico",F22="non agonistico"),G22<TODAY()),"🔴",IF(AND(OR(F22="agonistico",F22="non agonistico"),G22<=TODAY()+30),"🟡","🟢"))) -> 🟢 | Q22: =IF((L22+M22)<=0,"🟢",IF(N22<=0,"🔴",IF(O22>0,"🟡","🟢"))) -> 🟡
A23: 3 | B23: Gruppo 3 | C23: Matteo Bosso | D23: Michele Olly Olivieri | H23: =COUNTIFS(Presenze!$D:$D,D23,Presenze!$E:$E,"S") -> 0 | I23: =COUNTIFS(Presenze!$D:$D,D23,Presenze!$F:$F,"S") -> 0 | J23: =COUNTIFS(Presenze!$D:$D,D23,Presenze!$G:$G,"<>") -> 0 | K23: =I23-J23 -> 0 | L23: 360 | M23: 15 | N23: 135 | O23: =L23+M23-N23 -> 240 | P23: =IF(OR(F23="nessuno",F23=""),"🔴",IF(AND(OR(F23="agonistico",F23="non agonistico"),G23<TODAY()),"🔴",IF(AND(OR(F23="agonistico",F23="non agonistico"),G23<=TODAY()+30),"🟡","🟢"))) -> 🔴 | Q23: =IF((L23+M23)<=0,"🟢",IF(N23<=0,"🔴",IF(O23>0,"🟡","🟢"))) -> 🟡 | R23: CASH BOSSO
A24: 3 | B24: Gruppo 3 | C24: Matteo Bosso | D24: Eugenio Turri | F24: agonistico | G24: 46323 | H24: =COUNTIFS(Presenze!$D:$D,D24,Presenze!$E:$E,"S") -> 0 | I24: =COUNTIFS(Presenze!$D:$D,D24,Presenze!$F:$F,"S") -> 0 | J24: =COUNTIFS(Presenze!$D:$D,D24,Presenze!$G:$G,"<>") -> 0 | K24: =I24-J24 -> 0 | L24: 480 | M24: 15 | N24: 255 | O24: =L24+M24-N24 -> 240 | P24: =IF(OR(F24="nessuno",F24=""),"🔴",IF(AND(OR(F24="agonistico",F24="non agonistico"),G24<TODAY()),"🔴",IF(AND(OR(F24="agonistico",F24="non agonistico"),G24<=TODAY()+30),"🟡","🟢"))) -> 🟢 | Q24: =IF((L24+M24)<=0,"🟢",IF(N24<=0,"🔴",IF(O24>0,"🟡","🟢"))) -> 🟡 | R24: CASH OMAR
A25: 3 | B25: Gruppo 3 | C25: Matteo Bosso | D25: Federico Pastorello | F25: non agonistico | G25: 46332 | H25: =COUNTIFS(Presenze!$D:$D,D25,Presenze!$E:$E,"S") -> 0 | I25: =COUNTIFS(Presenze!$D:$D,D25,Presenze!$F:$F,"S") -> 0 | J25: =COUNTIFS(Presenze!$D:$D,D25,Presenze!$G:$G,"<>") -> 0 | K25: =I25-J25 -> 0 | L25: 480 | M25: 15 | N25: 255 | O25: =L25+M25-N25 -> 240 | P25: =IF(OR(F25="nessuno",F25=""),"🔴",IF(AND(OR(F25="agonistico",F25="non agonistico"),G25<TODAY()),"🔴",IF(AND(OR(F25="agonistico",F25="non agonistico"),G25<=TODAY()+30),"🟡","🟢"))) -> 🟢 | Q25: =IF((L25+M25)<=0,"🟢",IF(N25<=0,"🔴",IF(O25>0,"🟡","🟢"))) -> 🟡
A26: 4 | B26: Gruppo 4 | C26: Elena Colombi | D26: Federica Maccadanza | F26: agonistico | G26: 46304 | H26: =COUNTIFS(Presenze!$D:$D,D26,Presenze!$E:$E,"S") -> 0 | I26: =COUNTIFS(Presenze!$D:$D,D26,Presenze!$F:$F,"S") -> 0 | J26: =COUNTIFS(Presenze!$D:$D,D26,Presenze!$G:$G,"<>") -> 0 | K26: =I26-J26 -> 0 | L26: 480 | M26: 15 | N26: 255 | O26: =L26+M26-N26 -> 240 | P26: =IF(OR(F26="nessuno",F26=""),"🔴",IF(AND(OR(F26="agonistico",F26="non agonistico"),G26<TODAY()),"🔴",IF(AND(OR(F26="agonistico",F26="non agonistico"),G26<=TODAY()+30),"🟡","🟢"))) -> 🟢 | Q26: =IF((L26+M26)<=0,"🟢",IF(N26<=0,"🔴",IF(O26>0,"🟡","🟢"))) -> 🟡
A27: 4 | B27: Gruppo 4 | C27: Elena Colombi | D27: Francesca Basile | H27: =COUNTIFS(Presenze!$D:$D,D27,Presenze!$E:$E,"S") -> 0 | I27: =COUNTIFS(Presenze!$D:$D,D27,Presenze!$F:$F,"S") -> 0 | J27: =COUNTIFS(Presenze!$D:$D,D27,Presenze!$G:$G,"<>") -> 0 | K27: =I27-J27 -> 0 | L27: 480 | M27: 15 | N27: 255 | O27: =L27+M27-N27 -> 240 | P27: =IF(OR(F27="nessuno",F27=""),"🔴",IF(AND(OR(F27="agonistico",F27="non agonistico"),G27<TODAY()),"🔴",IF(AND(OR(F27="agonistico",F27="non agonistico"),G27<=TODAY()+30),"🟡","🟢"))) -> 🔴 | Q27: =IF((L27+M27)<=0,"🟢",IF(N27<=0,"🔴",IF(O27>0,"🟡","🟢"))) -> 🟡
A28: 4 | B28: Gruppo 4 | C28: Elena Colombi | D28: Veronica Maccadanza | F28: agonistico | G28: 46283 | H28: =COUNTIFS(Presenze!$D:$D,D28,Presenze!$E:$E,"S") -> 0 | I28: =COUNTIFS(Presenze!$D:$D,D28,Presenze!$F:$F,"S") -> 0 | J28: =COUNTIFS(Presenze!$D:$D,D28,Presenze!$G:$G,"<>") -> 0 | K28: =I28-J28 -> 0 | L28: 480 | M28: 15 | N28: 255 | O28: =L28+M28-N28 -> 240 | P28: =IF(OR(F28="nessuno",F28=""),"🔴",IF(AND(OR(F28="agonistico",F28="non agonistico"),G28<TODAY()),"🔴",IF(AND(OR(F28="agonistico",F28="non agonistico"),G28<=TODAY()+30),"🟡","🟢"))) -> 🟢 | Q28: =IF((L28+M28)<=0,"🟢",IF(N28<=0,"🔴",IF(O28>0,"🟡","🟢"))) -> 🟡
A29: 4 | B29: Gruppo 4 | C29: Elena Colombi | D29: Elisa Faraglia | F29: non agonistico | G29: 46294 | H29: =COUNTIFS(Presenze!$D:$D,D29,Presenze!$E:$E,"S") -> 0 | I29: =COUNTIFS(Presenze!$D:$D,D29,Presenze!$F:$F,"S") -> 0 | J29: =COUNTIFS(Presenze!$D:$D,D29,Presenze!$G:$G,"<>") -> 0 | K29: =I29-J29 -> 0 | L29: 480 | M29: 15 | N29: 255 | O29: =L29+M29-N29 -> 240 | P29: =IF(OR(F29="nessuno",F29=""),"🔴",IF(AND(OR(F29="agonistico",F29="non agonistico"),G29<TODAY()),"🔴",IF(AND(OR(F29="agonistico",F29="non agonistico"),G29<=TODAY()+30),"🟡","🟢"))) -> 🟢 | Q29: =IF((L29+M29)<=0,"🟢",IF(N29<=0,"🔴",IF(O29>0,"🟡","🟢"))) -> 🟡
A30: 4 | B30: Gruppo 4 | C30: Elena Colombi | D30: Stefania Prando Moglie Mattia | F30: agonistico | G30: 46042 | H30: =COUNTIFS(Presenze!$D:$D,D30,Presenze!$E:$E,"S") -> 0 | I30: =COUNTIFS(Presenze!$D:$D,D30,Presenze!$F:$F,"S") -> 0 | J30: =COUNTIFS(Presenze!$D:$D,D30,Presenze!$G:$G,"<>") -> 0 | K30: =I30-J30 -> 0 | L30: 480 | M30: 15 | N30: 255 | O30: =L30+M30-N30 -> 240 | P30: =IF(OR(F30="nessuno",F30=""),"🔴",IF(AND(OR(F30="agonistico",F30="non agonistico"),G30<TODAY()),"🔴",IF(AND(OR(F30="agonistico",F30="non agonistico"),G30<=TODAY()+30),"🟡","🟢"))) -> 🟡 | Q30: =IF((L30+M30)<=0,"🟢",IF(N30<=0,"🔴",IF(O30>0,"🟡","🟢"))) -> 🟡
A31: 4 | B31: Gruppo 4 | C31: Elena Colombi | D31: Valentina Bernori | F31: agonistico | G31: 46258 | H31: =COUNTIFS(Presenze!$D:$D,D31,Presenze!$E:$E,"S") -> 0 | I31: =COUNTIFS(Presenze!$D:$D,D31,Presenze!$F:$F,"S") -> 0 | J31: =COUNTIFS(Presenze!$D:$D,D31,Presenze!$G:$G,"<>") -> 0 | K31: =I31-J31 -> 0 | L31: 480 | M31: 15 | N31: 255 | O31: =L31+M31-N31 -> 240 | P31: =IF(OR(F31="nessuno",F31=""),"🔴",IF(AND(OR(F31="agonistico",F31="non agonistico"),G31<TODAY()),"🔴",IF(AND(OR(F31="agonistico",F31="non agonistico"),G31<=TODAY()+30),"🟡","🟢"))) -> 🟢 | Q31: =IF((L31+M31)<=0,"🟢",IF(N31<=0,"🔴",IF(O31>0,"🟡","🟢"))) -> 🟡
A32: 4 | B32: Gruppo 4 | C32: Elena Colombi | D32: Valeria Marconi | F32: agonistico | G32: 46106 | H32: =COUNTIFS(Presenze!$D:$D,D32,Presenze!$E:$E,"S") -> 0 | I32: =COUNTIFS(Presenze!$D:$D,D32,Presenze!$F:$F,"S") -> 0 | J32: =COUNTIFS(Presenze!$D:$D,D32,Presenze!$G:$G,"<>") -> 0 | K32: =I32-J32 -> 0 | L32: 315 | M32: 15 | N32: 90 | O32: =L32+M32-N32 -> 240 | P32: =IF(OR(F32="nessuno",F32=""),"🔴",IF(AND(OR(F32="agonistico",F32="non agonistico"),G32<TODAY()),"🔴",IF(AND(OR(F32="agonistico",F32="non agonistico"),G32<=TODAY()+30),"🟡","🟢"))) -> 🟢 | Q32: =IF((L32+M32)<=0,"🟢",IF(N32<=0,"🔴",IF(O32>0,"🟡","🟢"))) -> 🟡
A33: 4 | B33: Gruppo 4 | C33: Elena Colombi | D33: Camilla Ederle | F33: agonistico | G33: 46301 | H33: =COUNTIFS(Presenze!$D:$D,D33,Presenze!$E:$E,"S") -> 0 | I33: =COUNTIFS(Presenze!$D:$D,D33,Presenze!$F:$F,"S") -> 0 | J33: =COUNTIFS(Presenze!$D:$D,D33,Presenze!$G:$G,"<>") -> 0 | K33: =I33-J33 -> 0 | L33: 480 | M33: 15 | N33: 255 | O33: =L33+M33-N33 -> 240 | P33: =IF(OR(F33="nessuno",F33=""),"🔴",IF(AND(OR(F33="agonistico",F33="non agonistico"),G33<TODAY()),"🔴",IF(AND(OR(F33="agonistico",F33="non agonistico"),G33<=TODAY()+30),"🟡","🟢"))) -> 🟢 | Q33: =IF((L33+M33)<=0,"🟢",IF(N33<=0,"🔴",IF(O33>0,"🟡","🟢"))) -> 🟡
A34: 5 | B34: Gruppo 5 | C34: Matteo Bosso | D34: Mattia Morati | F34: agonistico | G34: 46343 | H34: =COUNTIFS(Presenze!$D:$D,D34,Presenze!$E:$E,"S") -> 0 | I34: =COUNTIFS(Presenze!$D:$D,D34,Presenze!$F:$F,"S") -> 0 | J34: =COUNTIFS(Presenze!$D:$D,D34,Presenze!$G:$G,"<>") -> 0 | K34: =I34-J34 -> 0 | L34: 480 | M34: 15 | N34: 255 | O34: =L34+M34-N34 -> 240 | P34: =IF(OR(F34="nessuno",F34=""),"🔴",IF(AND(OR(F34="agonistico",F34="non agonistico"),G34<TODAY()),"🔴",IF(AND(OR(F34="agonistico",F34="non agonistico"),G34<=TODAY()+30),"🟡","🟢"))) -> 🟢 | Q34: =IF((L34+M34)<=0,"🟢",IF(N34<=0,"🔴",IF(O34>0,"🟡","🟢"))) -> 🟡
A35: 5 | B35: Gruppo 5 | C35: Matteo Bosso | D35: Luigi Nardiello | F35: agonistico | G35: 46308 | H35: =COUNTIFS(Presenze!$D:$D,D35,Presenze!$E:$E,"S") -> 0 | I35: =COUNTIFS(Presenze!$D:$D,D35,Presenze!$F:$F,"S") -> 0 | J35: =COUNTIFS(Presenze!$D:$D,D35,Presenze!$G:$G,"<>") -> 0 | K35: =I35-J35 -> 0 | L35: 480 | M35: 15 | N35: 255 | O35: =L35+M35-N35 -> 240 | P35: =IF(OR(F35="nessuno",F35=""),"🔴",IF(AND(OR(F35="agonistico",F35="non agonistico"),G35<TODAY()),"🔴",IF(AND(OR(F35="agonistico",F35="non agonistico"),G35<=TODAY()+30),"🟡","🟢"))) -> 🟢 | Q35: =IF((L35+M35)<=0,"🟢",IF(N35<=0,"🔴",IF(O35>0,"🟡","🟢"))) -> 🟡
A36: 5 | B36: Gruppo 5 | C36: Matteo Bosso | D36: Marco Scherlich | F36: agonistico | G36: 46058 | H36: =COUNTIFS(Presenze!$D:$D,D36,Presenze!$E:$E,"S") -> 0 | I36: =COUNTIFS(Presenze!$D:$D,D36,Presenze!$F:$F,"S") -> 0 | J36: =COUNTIFS(Presenze!$D:$D,D36,Presenze!$G:$G,"<>") -> 0 | K36: =I36-J36 -> 0 | L36: 860 | M36: 15 | N36: 445 | O36: =L36+M36-N36 -> 430 | P36: =IF(OR(F36="nessuno",F36=""),"🔴",IF(AND(OR(F36="agonistico",F36="non agonistico"),G36<TODAY()),"🔴",IF(AND(OR(F36="agonistico",F36="non agonistico"),G36<=TODAY()+30),"🟡","🟢"))) -> 🟡 | Q36: =IF((L36+M36)<=0,"🟢",IF(N36<=0,"🔴",IF(O36>0,"🟡","🟢"))) -> 🟡
A37: 5 | B37: Gruppo 5 | C37: Matteo Bosso | D37: Alberto Turco | F37: agonistico | G37: 46321 | H37: =COUNTIFS(Presenze!$D:$D,D37,Presenze!$E:$E,"S") -> 0 | I37: =COUNTIFS(Presenze!$D:$D,D37,Presenze!$F:$F,"S") -> 0 | J37: =COUNTIFS(Presenze!$D:$D,D37,Presenze!$G:$G,"<>") -> 0 | K37: =I37-J37 -> 0 | L37: 480 | M37: 15 | N37: 255 | O37: =L37+M37-N37 -> 240 | P37: =IF(OR(F37="nessuno",F37=""),"🔴",IF(AND(OR(F37="agonistico",F37="non agonistico"),G37<TODAY()),"🔴",IF(AND(OR(F37="agonistico",F37="non agonistico"),G37<=TODAY()+30),"🟡","🟢"))) -> 🟢 | Q37: =IF((L37+M37)<=0,"🟢",IF(N37<=0,"🔴",IF(O37>0,"🟡","🟢"))) -> 🟡
A38: 5 | B38: Gruppo 5 | C38: Matteo Bosso | D38: Luca Bertoldo | F38: non agonistico | G38: 46297 | H38: =COUNTIFS(Presenze!$D:$D,D38,Presenze!$E:$E,"S") -> 0 | I38: =COUNTIFS(Presenze!$D:$D,D38,Presenze!$F:$F,"S") -> 0 | J38: =COUNTIFS(Presenze!$D:$D,D38,Presenze!$G:$G,"<>") -> 0 | K38: =I38-J38 -> 0 | L38: 480 | M38: 15 | N38: 255 | O38: =L38+M38-N38 -> 240 | P38: =IF(OR(F38="nessuno",F38=""),"🔴",IF(AND(OR(F38="agonistico",F38="non agonistico"),G38<TODAY()),"🔴",IF(AND(OR(F38="agonistico",F38="non agonistico"),G38<=TODAY()+30),"🟡","🟢"))) -> 🟢 | Q38: =IF((L38+M38)<=0,"🟢",IF(N38<=0,"🔴",IF(O38>0,"🟡","🟢"))) -> 🟡
A39: 5 | B39: Gruppo 5 | C39: Matteo Bosso | D39: Omar Franzini | F39: agonistico | G39: 46275 | H39: =COUNTIFS(Presenze!$D:$D,D39,Presenze!$E:$E,"S") -> 0 | I39: =COUNTIFS(Presenze!$D:$D,D39,Presenze!$F:$F,"S") -> 0 | J39: =COUNTIFS(Presenze!$D:$D,D39,Presenze!$G:$G,"<>") -> 0 | K39: =I39-J39 -> 0 | L39: 480 | M39: 15 | N39: 255 | O39: =L39+M39-N39 -> 240 | P39: =IF(OR(F39="nessuno",F39=""),"🔴",IF(AND(OR(F39="agonistico",F39="non agonistico"),G39<TODAY()),"🔴",IF(AND(OR(F39="agonistico",F39="non agonistico"),G39<=TODAY()+30),"🟡","🟢"))) -> 🟢 | Q39: =IF((L39+M39)<=0,"🟢",IF(N39<=0,"🔴",IF(O39>0,"🟡","🟢"))) -> 🟡
A40: 5 | B40: Gruppo 5 | C40: Matteo Bosso | D40: Fabio Guarnati | H40: =COUNTIFS(Presenze!$D:$D,D40,Presenze!$E:$E,"S") -> 0 | I40: =COUNTIFS(Presenze!$D:$D,D40,Presenze!$F:$F,"S") -> 0 | J40: =COUNTIFS(Presenze!$D:$D,D40,Presenze!$G:$G,"<>") -> 0 | K40: =I40-J40 -> 0 | L40: 285 | M40: 15 | N40: 0 | O40: =L40+M40-N40 -> 300 | P40: =IF(OR(F40="nessuno",F40=""),"🔴",IF(AND(OR(F40="agonistico",F40="non agonistico"),G40<TODAY()),"🔴",IF(AND(OR(F40="agonistico",F40="non agonistico"),G40<=TODAY()+30),"🟡","🟢"))) -> 🔴 | Q40: =IF((L40+M40)<=0,"🟢",IF(N40<=0,"🔴",IF(O40>0,"🟡","🟢"))) -> 🔴
...

Sheet Presenze
A1: Data | B1: ID Gruppo | C1: Nome Gruppo | D1: Atleta | E1: Presente (S/N) | F1: Assenza da recuperare? (S/N) | G1: Data recupero | H1: Gruppo in cui recupera | I1: Note
C6: =IFERROR(INDEX(Gruppi_Atleti!$B$2:$B$122,MATCH(B6,Gruppi_Atleti!$A$2:$A$122,0)),"")
C7: =IFERROR(INDEX(Gruppi_Atleti!$B$2:$B$122,MATCH(B7,Gruppi_Atleti!$A$2:$A$122,0)),"")
C8: =IFERROR(INDEX(Gruppi_Atleti!$B$2:$B$122,MATCH(B8,Gruppi_Atleti!$A$2:$A$122,0)),"")
C9: =IFERROR(INDEX(Gruppi_Atleti!$B$2:$B$122,MATCH(B9,Gruppi_Atleti!$A$2:$A$122,0)),"")
C10: =IFERROR(INDEX(Gruppi_Atleti!$B$2:$B$122,MATCH(B10,Gruppi_Atleti!$A$2:$A$122,0)),"")
C11: =IFERROR(INDEX(Gruppi_Atleti!$B$2:$B$122,MATCH(B11,Gruppi_Atleti!$A$2:$A$122,0)),"")
C12: =IFERROR(INDEX(Gruppi_Atleti!$B$2:$B$122,MATCH(B12,Gruppi_Atleti!$A$2:$A$122,0)),"")
C13: =IFERROR(INDEX(Gruppi_Atleti!$B$2:$B$122,MATCH(B13,Gruppi_Atleti!$A$2:$A$122,0)),"")
C14: =IFERROR(INDEX(Gruppi_Atleti!$B$2:$B$122,MATCH(B14,Gruppi_Atleti!$A$2:$A$122,0)),"")
C15: =IFERROR(INDEX(Gruppi_Atleti!$B$2:$B$122,MATCH(B15,Gruppi_Atleti!$A$2:$A$122,0)),"")
C16: =IFERROR(INDEX(Gruppi_Atleti!$B$2:$B$122,MATCH(B16,Gruppi_Atleti!$A$2:$A$122,0)),"")
C17: =IFERROR(INDEX(Gruppi_Atleti!$B$2:$B$122,MATCH(B17,Gruppi_Atleti!$A$2:$A$122,0)),"")
... C1000: =IFERROR(INDEX(Gruppi_Atleti!$B$2:$B$122,MATCH(B1000,Gruppi_Atleti!$A$2:$A$122,0)),"")

Sheet Disponibilità_Recuperi
A1: ID Gruppo | B1: Nome Gruppo | C1: Giorno/Orario | D1: Posti disponibili | E1: Extra note
A2: 1 | B2: Gruppo 1
A3: 2 | B3: Gruppo 2
A4: 3 | B4: Gruppo 3
A5: 4 | B5: Gruppo 4
A6: 5 | B6: Gruppo 5
A7: 6 | B7: Gruppo 6
A8: 7 | B8: Gruppo 7
A9: 8 | B9: Gruppo 8
A10: 9 | B10: Gruppo 9
A11: 10 | B11: Gruppo 10
A12: 11 | B12: Gruppo 11
A13: 12 | B13: Gruppo 12
... A18: 17 | B18: Gruppo 17
A20: Atleta | B20: Gruppo di origine | C20: Assenze da recuperare | D20: Recuperi fatti | E20: Recuperi da programmare
